[2025-05-31 18:16:23] ===== AUTOFIX SESSION STARTED =====
[2025-05-31 18:16:23] 
=== ATTEMPT 1/15 ===
[2025-05-31 18:16:23] Starting script: C:\Users\Lenovo\.spyder-py3\xtts_match_embed.py
[2025-05-31 18:16:26] Script exited with code: 1
[2025-05-31 18:16:26] Failure signature detected
[2025-05-31 18:16:26] ERROR detected | Radical: False
Traceback (most recent call last):
File "C:\Users\Lenovo\.spyder-py3\xtts_match_embed.py", line 5, in <module>
import librosa
ModuleNotFoundError: No module named 'librosa'...
[2025-05-31 18:16:26] Autofix initiated | Radical mode: False
[2025-05-31 18:16:26] Sending API request | Tokens: ~715
[2025-05-31 18:16:26] Prompt context: 
You are CodeMedic v2.5, a fault-tolerant Python repair agent. You're repairing `xtts_match_embed.py` which extracts phonetic embeddings using Coqui XTTS v2.

# CONTEXT:
Current date: 2025-05-31
Target environment: Windows 11, Python 3.9, PyTorch 2.0+
Previous error: Traceback (most recent call last...
[2025-05-31 18:16:27] API response: 400 | Time: 0.44s
[2025-05-31 18:16:27] API error: {"error":{"message":"Model Not Exist","type":"invalid_request_error","param":null,"code":"invalid_request_error"}}
[2025-05-31 18:16:27] Backup created: C:\Users\Lenovo\.spyder-py3\xtts_match_embed.py.bak1
[2025-05-31 18:16:27] Applied repaired code
[2025-05-31 18:16:27] 
=== ATTEMPT 2/15 ===
[2025-05-31 18:16:27] Starting script: C:\Users\Lenovo\.spyder-py3\xtts_match_embed.py
[2025-05-31 18:16:29] Script exited with code: 1
[2025-05-31 18:16:29] Failure signature detected
[2025-05-31 18:16:29] ERROR detected | Radical: False
Traceback (most recent call last):
File "C:\Users\Lenovo\.spyder-py3\xtts_match_embed.py", line 5, in <module>
import librosa
ModuleNotFoundError: No module named 'librosa'...
[2025-05-31 18:16:29] Autofix initiated | Radical mode: False
[2025-05-31 18:16:29] Sending API request | Tokens: ~715
[2025-05-31 18:16:29] Prompt context: 
You are CodeMedic v2.5, a fault-tolerant Python repair agent. You're repairing `xtts_match_embed.py` which extracts phonetic embeddings using Coqui XTTS v2.

# CONTEXT:
Current date: 2025-05-31
Target environment: Windows 11, Python 3.9, PyTorch 2.0+
Previous error: Traceback (most recent call last...
[2025-05-31 18:16:30] API response: 400 | Time: 0.87s
[2025-05-31 18:16:30] API error: {"error":{"message":"Model Not Exist","type":"invalid_request_error","param":null,"code":"invalid_request_error"}}
[2025-05-31 18:16:30] Backup created: C:\Users\Lenovo\.spyder-py3\xtts_match_embed.py.bak2
[2025-05-31 18:16:30] Applied repaired code
[2025-05-31 18:16:30] 
=== ATTEMPT 3/15 ===
[2025-05-31 18:16:30] Starting script: C:\Users\Lenovo\.spyder-py3\xtts_match_embed.py
[2025-05-31 18:16:33] Script exited with code: 1
[2025-05-31 18:16:33] Failure signature detected
[2025-05-31 18:16:33] ERROR detected | Radical: True
Traceback (most recent call last):
File "C:\Users\Lenovo\.spyder-py3\xtts_match_embed.py", line 5, in <module>
import librosa
ModuleNotFoundError: No module named 'librosa'...
[2025-05-31 18:16:33] Autofix initiated | Radical mode: True
[2025-05-31 18:16:33] Sending API request | Tokens: ~730
[2025-05-31 18:16:33] Prompt context: 
You are CodeMedic v2.5, a fault-tolerant Python repair agent. You're repairing `xtts_match_embed.py` which extracts phonetic embeddings using Coqui XTTS v2.

# CONTEXT:
Current date: 2025-05-31
Target environment: Windows 11, Python 3.9, PyTorch 2.0+
Previous error: Traceback (most recent call last...
[2025-05-31 18:16:33] API response: 400 | Time: 0.41s
[2025-05-31 18:16:33] API error: {"error":{"message":"Model Not Exist","type":"invalid_request_error","param":null,"code":"invalid_request_error"}}
[2025-05-31 18:16:33] Backup created: C:\Users\Lenovo\.spyder-py3\xtts_match_embed.py.bak3
[2025-05-31 18:16:33] Applied repaired code
[2025-05-31 18:16:33] 
=== ATTEMPT 4/15 ===
[2025-05-31 18:16:33] Starting script: C:\Users\Lenovo\.spyder-py3\xtts_match_embed.py
[2025-05-31 18:16:36] Script exited with code: 1
[2025-05-31 18:16:36] Failure signature detected
[2025-05-31 18:16:36] ERROR detected | Radical: True
Traceback (most recent call last):
File "C:\Users\Lenovo\.spyder-py3\xtts_match_embed.py", line 5, in <module>
import librosa
ModuleNotFoundError: No module named 'librosa'...
[2025-05-31 18:16:36] Autofix initiated | Radical mode: True
[2025-05-31 18:16:36] Sending API request | Tokens: ~730
[2025-05-31 18:16:36] Prompt context: 
You are CodeMedic v2.5, a fault-tolerant Python repair agent. You're repairing `xtts_match_embed.py` which extracts phonetic embeddings using Coqui XTTS v2.

# CONTEXT:
Current date: 2025-05-31
Target environment: Windows 11, Python 3.9, PyTorch 2.0+
Previous error: Traceback (most recent call last...
[2025-05-31 18:16:37] API response: 400 | Time: 0.37s
[2025-05-31 18:16:37] API error: {"error":{"message":"Model Not Exist","type":"invalid_request_error","param":null,"code":"invalid_request_error"}}
[2025-05-31 18:16:37] Backup created: C:\Users\Lenovo\.spyder-py3\xtts_match_embed.py.bak4
[2025-05-31 18:16:37] Applied repaired code
[2025-05-31 18:16:37] 
=== ATTEMPT 5/15 ===
[2025-05-31 18:16:37] Starting script: C:\Users\Lenovo\.spyder-py3\xtts_match_embed.py
[2025-05-31 18:16:40] Script exited with code: 1
[2025-05-31 18:16:40] Failure signature detected
[2025-05-31 18:16:40] ERROR detected | Radical: True
Traceback (most recent call last):
File "C:\Users\Lenovo\.spyder-py3\xtts_match_embed.py", line 5, in <module>
import librosa
ModuleNotFoundError: No module named 'librosa'...
[2025-05-31 18:16:40] Autofix initiated | Radical mode: True
[2025-05-31 18:16:40] Sending API request | Tokens: ~730
[2025-05-31 18:16:40] Prompt context: 
You are CodeMedic v2.5, a fault-tolerant Python repair agent. You're repairing `xtts_match_embed.py` which extracts phonetic embeddings using Coqui XTTS v2.

# CONTEXT:
Current date: 2025-05-31
Target environment: Windows 11, Python 3.9, PyTorch 2.0+
Previous error: Traceback (most recent call last...
[2025-05-31 18:16:40] API response: 400 | Time: 0.43s
[2025-05-31 18:16:40] API error: {"error":{"message":"Model Not Exist","type":"invalid_request_error","param":null,"code":"invalid_request_error"}}
[2025-05-31 18:16:40] Backup created: C:\Users\Lenovo\.spyder-py3\xtts_match_embed.py.bak5
[2025-05-31 18:16:40] Applied repaired code
[2025-05-31 18:16:40] 
=== ATTEMPT 6/15 ===
[2025-05-31 18:16:40] Starting script: C:\Users\Lenovo\.spyder-py3\xtts_match_embed.py
[2025-05-31 18:16:43] Script exited with code: 1
[2025-05-31 18:16:43] Failure signature detected
[2025-05-31 18:16:43] ERROR detected | Radical: True
Traceback (most recent call last):
File "C:\Users\Lenovo\.spyder-py3\xtts_match_embed.py", line 5, in <module>
import librosa
ModuleNotFoundError: No module named 'librosa'...
[2025-05-31 18:16:43] Autofix initiated | Radical mode: True
[2025-05-31 18:16:43] Sending API request | Tokens: ~730
[2025-05-31 18:16:43] Prompt context: 
You are CodeMedic v2.5, a fault-tolerant Python repair agent. You're repairing `xtts_match_embed.py` which extracts phonetic embeddings using Coqui XTTS v2.

# CONTEXT:
Current date: 2025-05-31
Target environment: Windows 11, Python 3.9, PyTorch 2.0+
Previous error: Traceback (most recent call last...
[2025-05-31 18:16:43] API response: 400 | Time: 0.42s
[2025-05-31 18:16:43] API error: {"error":{"message":"Model Not Exist","type":"invalid_request_error","param":null,"code":"invalid_request_error"}}
[2025-05-31 18:16:43] Backup created: C:\Users\Lenovo\.spyder-py3\xtts_match_embed.py.bak6
[2025-05-31 18:16:43] Applied repaired code
[2025-05-31 18:16:43] 
=== ATTEMPT 7/15 ===
[2025-05-31 18:16:43] Starting script: C:\Users\Lenovo\.spyder-py3\xtts_match_embed.py
[2025-05-31 18:16:46] Script exited with code: 1
[2025-05-31 18:16:46] Failure signature detected
[2025-05-31 18:16:46] ERROR detected | Radical: True
Traceback (most recent call last):
File "C:\Users\Lenovo\.spyder-py3\xtts_match_embed.py", line 5, in <module>
import librosa
ModuleNotFoundError: No module named 'librosa'...
[2025-05-31 18:16:46] Autofix initiated | Radical mode: True
[2025-05-31 18:16:46] Sending API request | Tokens: ~730
[2025-05-31 18:16:46] Prompt context: 
You are CodeMedic v2.5, a fault-tolerant Python repair agent. You're repairing `xtts_match_embed.py` which extracts phonetic embeddings using Coqui XTTS v2.

# CONTEXT:
Current date: 2025-05-31
Target environment: Windows 11, Python 3.9, PyTorch 2.0+
Previous error: Traceback (most recent call last...
[2025-05-31 18:16:46] API response: 400 | Time: 0.40s
[2025-05-31 18:16:46] API error: {"error":{"message":"Model Not Exist","type":"invalid_request_error","param":null,"code":"invalid_request_error"}}
[2025-05-31 18:16:46] Backup created: C:\Users\Lenovo\.spyder-py3\xtts_match_embed.py.bak7
[2025-05-31 18:16:46] Applied repaired code
[2025-05-31 18:16:46] 
=== ATTEMPT 8/15 ===
[2025-05-31 18:16:46] Starting script: C:\Users\Lenovo\.spyder-py3\xtts_match_embed.py
[2025-05-31 18:16:49] Script exited with code: 1
[2025-05-31 18:16:49] Failure signature detected
[2025-05-31 18:16:49] ERROR detected | Radical: True
Traceback (most recent call last):
File "C:\Users\Lenovo\.spyder-py3\xtts_match_embed.py", line 5, in <module>
import librosa
ModuleNotFoundError: No module named 'librosa'...
[2025-05-31 18:16:49] Autofix initiated | Radical mode: True
[2025-05-31 18:16:49] Sending API request | Tokens: ~730
[2025-05-31 18:16:49] Prompt context: 
You are CodeMedic v2.5, a fault-tolerant Python repair agent. You're repairing `xtts_match_embed.py` which extracts phonetic embeddings using Coqui XTTS v2.

# CONTEXT:
Current date: 2025-05-31
Target environment: Windows 11, Python 3.9, PyTorch 2.0+
Previous error: Traceback (most recent call last...
[2025-05-31 18:16:49] API response: 400 | Time: 0.39s
[2025-05-31 18:16:49] API error: {"error":{"message":"Model Not Exist","type":"invalid_request_error","param":null,"code":"invalid_request_error"}}
[2025-05-31 18:16:49] Backup created: C:\Users\Lenovo\.spyder-py3\xtts_match_embed.py.bak8
[2025-05-31 18:16:49] Applied repaired code
[2025-05-31 18:16:49] 
=== ATTEMPT 9/15 ===
[2025-05-31 18:16:49] Starting script: C:\Users\Lenovo\.spyder-py3\xtts_match_embed.py
[2025-05-31 18:16:52] Script exited with code: 1
[2025-05-31 18:16:52] Failure signature detected
[2025-05-31 18:16:52] ERROR detected | Radical: True
Traceback (most recent call last):
File "C:\Users\Lenovo\.spyder-py3\xtts_match_embed.py", line 5, in <module>
import librosa
ModuleNotFoundError: No module named 'librosa'...
[2025-05-31 18:16:52] Autofix initiated | Radical mode: True
[2025-05-31 18:16:52] Sending API request | Tokens: ~730
[2025-05-31 18:16:52] Prompt context: 
You are CodeMedic v2.5, a fault-tolerant Python repair agent. You're repairing `xtts_match_embed.py` which extracts phonetic embeddings using Coqui XTTS v2.

# CONTEXT:
Current date: 2025-05-31
Target environment: Windows 11, Python 3.9, PyTorch 2.0+
Previous error: Traceback (most recent call last...
[2025-05-31 18:16:53] API response: 400 | Time: 0.41s
[2025-05-31 18:16:53] API error: {"error":{"message":"Model Not Exist","type":"invalid_request_error","param":null,"code":"invalid_request_error"}}
[2025-05-31 18:16:53] Backup created: C:\Users\Lenovo\.spyder-py3\xtts_match_embed.py.bak9
[2025-05-31 18:16:53] Applied repaired code
[2025-05-31 18:16:53] 
=== ATTEMPT 10/15 ===
[2025-05-31 18:16:53] Starting script: C:\Users\Lenovo\.spyder-py3\xtts_match_embed.py
[2025-05-31 18:16:55] Script exited with code: 1
[2025-05-31 18:16:55] Failure signature detected
[2025-05-31 18:16:55] ERROR detected | Radical: True
Traceback (most recent call last):
File "C:\Users\Lenovo\.spyder-py3\xtts_match_embed.py", line 5, in <module>
import librosa
ModuleNotFoundError: No module named 'librosa'...
[2025-05-31 18:16:55] Autofix initiated | Radical mode: True
[2025-05-31 18:16:55] Sending API request | Tokens: ~730
[2025-05-31 18:16:55] Prompt context: 
You are CodeMedic v2.5, a fault-tolerant Python repair agent. You're repairing `xtts_match_embed.py` which extracts phonetic embeddings using Coqui XTTS v2.

# CONTEXT:
Current date: 2025-05-31
Target environment: Windows 11, Python 3.9, PyTorch 2.0+
Previous error: Traceback (most recent call last...
[2025-05-31 18:16:56] API response: 400 | Time: 0.37s
[2025-05-31 18:16:56] API error: {"error":{"message":"Model Not Exist","type":"invalid_request_error","param":null,"code":"invalid_request_error"}}
[2025-05-31 18:16:56] Backup created: C:\Users\Lenovo\.spyder-py3\xtts_match_embed.py.bak10
[2025-05-31 18:16:56] Applied repaired code
[2025-05-31 18:16:56] 
=== ATTEMPT 11/15 ===
[2025-05-31 18:16:56] Starting script: C:\Users\Lenovo\.spyder-py3\xtts_match_embed.py
[2025-05-31 18:16:58] Script exited with code: 1
[2025-05-31 18:16:58] Failure signature detected
[2025-05-31 18:16:58] ERROR detected | Radical: True
Traceback (most recent call last):
File "C:\Users\Lenovo\.spyder-py3\xtts_match_embed.py", line 5, in <module>
import librosa
ModuleNotFoundError: No module named 'librosa'...
[2025-05-31 18:16:58] Autofix initiated | Radical mode: True
[2025-05-31 18:16:58] Sending API request | Tokens: ~730
[2025-05-31 18:16:58] Prompt context: 
You are CodeMedic v2.5, a fault-tolerant Python repair agent. You're repairing `xtts_match_embed.py` which extracts phonetic embeddings using Coqui XTTS v2.

# CONTEXT:
Current date: 2025-05-31
Target environment: Windows 11, Python 3.9, PyTorch 2.0+
Previous error: Traceback (most recent call last...
[2025-05-31 18:16:59] API response: 400 | Time: 0.44s
[2025-05-31 18:16:59] API error: {"error":{"message":"Model Not Exist","type":"invalid_request_error","param":null,"code":"invalid_request_error"}}
[2025-05-31 18:16:59] Backup created: C:\Users\Lenovo\.spyder-py3\xtts_match_embed.py.bak11
[2025-05-31 18:16:59] Applied repaired code
[2025-05-31 18:16:59] 
=== ATTEMPT 12/15 ===
[2025-05-31 18:16:59] Starting script: C:\Users\Lenovo\.spyder-py3\xtts_match_embed.py
[2025-05-31 18:17:02] Script exited with code: 1
[2025-05-31 18:17:02] Failure signature detected
[2025-05-31 18:17:02] ERROR detected | Radical: True
Traceback (most recent call last):
File "C:\Users\Lenovo\.spyder-py3\xtts_match_embed.py", line 5, in <module>
import librosa
ModuleNotFoundError: No module named 'librosa'...
[2025-05-31 18:17:02] Autofix initiated | Radical mode: True
[2025-05-31 18:17:02] Sending API request | Tokens: ~730
[2025-05-31 18:17:02] Prompt context: 
You are CodeMedic v2.5, a fault-tolerant Python repair agent. You're repairing `xtts_match_embed.py` which extracts phonetic embeddings using Coqui XTTS v2.

# CONTEXT:
Current date: 2025-05-31
Target environment: Windows 11, Python 3.9, PyTorch 2.0+
Previous error: Traceback (most recent call last...
[2025-05-31 18:17:02] API response: 400 | Time: 0.40s
[2025-05-31 18:17:02] API error: {"error":{"message":"Model Not Exist","type":"invalid_request_error","param":null,"code":"invalid_request_error"}}
[2025-05-31 18:17:02] Backup created: C:\Users\Lenovo\.spyder-py3\xtts_match_embed.py.bak12
[2025-05-31 18:17:02] Applied repaired code
[2025-05-31 18:17:02] 
=== ATTEMPT 13/15 ===
[2025-05-31 18:17:02] Starting script: C:\Users\Lenovo\.spyder-py3\xtts_match_embed.py
[2025-05-31 18:17:04] Script exited with code: 1
[2025-05-31 18:17:04] Failure signature detected
[2025-05-31 18:17:04] ERROR detected | Radical: True
Traceback (most recent call last):
File "C:\Users\Lenovo\.spyder-py3\xtts_match_embed.py", line 5, in <module>
import librosa
ModuleNotFoundError: No module named 'librosa'...
[2025-05-31 18:17:04] Autofix initiated | Radical mode: True
[2025-05-31 18:17:04] Sending API request | Tokens: ~730
[2025-05-31 18:17:04] Prompt context: 
You are CodeMedic v2.5, a fault-tolerant Python repair agent. You're repairing `xtts_match_embed.py` which extracts phonetic embeddings using Coqui XTTS v2.

# CONTEXT:
Current date: 2025-05-31
Target environment: Windows 11, Python 3.9, PyTorch 2.0+
Previous error: Traceback (most recent call last...
[2025-05-31 18:17:05] API response: 400 | Time: 0.38s
[2025-05-31 18:17:05] API error: {"error":{"message":"Model Not Exist","type":"invalid_request_error","param":null,"code":"invalid_request_error"}}
[2025-05-31 18:17:05] Backup created: C:\Users\Lenovo\.spyder-py3\xtts_match_embed.py.bak13
[2025-05-31 18:17:05] Applied repaired code
[2025-05-31 18:17:05] 
=== ATTEMPT 14/15 ===
[2025-05-31 18:17:05] Starting script: C:\Users\Lenovo\.spyder-py3\xtts_match_embed.py
[2025-05-31 18:17:08] Script exited with code: 1
[2025-05-31 18:17:08] Failure signature detected
[2025-05-31 18:17:08] ERROR detected | Radical: True
Traceback (most recent call last):
File "C:\Users\Lenovo\.spyder-py3\xtts_match_embed.py", line 5, in <module>
import librosa
ModuleNotFoundError: No module named 'librosa'...
[2025-05-31 18:17:08] Autofix initiated | Radical mode: True
[2025-05-31 18:17:08] Sending API request | Tokens: ~730
[2025-05-31 18:17:08] Prompt context: 
You are CodeMedic v2.5, a fault-tolerant Python repair agent. You're repairing `xtts_match_embed.py` which extracts phonetic embeddings using Coqui XTTS v2.

# CONTEXT:
Current date: 2025-05-31
Target environment: Windows 11, Python 3.9, PyTorch 2.0+
Previous error: Traceback (most recent call last...
[2025-05-31 18:17:08] API response: 400 | Time: 0.37s
[2025-05-31 18:17:08] API error: {"error":{"message":"Model Not Exist","type":"invalid_request_error","param":null,"code":"invalid_request_error"}}
[2025-05-31 18:17:08] Backup created: C:\Users\Lenovo\.spyder-py3\xtts_match_embed.py.bak14
[2025-05-31 18:17:08] Applied repaired code
[2025-05-31 18:17:08] 
=== ATTEMPT 15/15 ===
[2025-05-31 18:17:08] Starting script: C:\Users\Lenovo\.spyder-py3\xtts_match_embed.py
[2025-05-31 18:17:11] Script exited with code: 1
[2025-05-31 18:17:11] Failure signature detected
[2025-05-31 18:17:11] ERROR detected | Radical: True
Traceback (most recent call last):
File "C:\Users\Lenovo\.spyder-py3\xtts_match_embed.py", line 5, in <module>
import librosa
ModuleNotFoundError: No module named 'librosa'...
[2025-05-31 18:17:11] Autofix initiated | Radical mode: True
[2025-05-31 18:17:11] Sending API request | Tokens: ~730
[2025-05-31 18:17:11] Prompt context: 
You are CodeMedic v2.5, a fault-tolerant Python repair agent. You're repairing `xtts_match_embed.py` which extracts phonetic embeddings using Coqui XTTS v2.

# CONTEXT:
Current date: 2025-05-31
Target environment: Windows 11, Python 3.9, PyTorch 2.0+
Previous error: Traceback (most recent call last...
[2025-05-31 18:17:11] API response: 400 | Time: 0.39s
[2025-05-31 18:17:11] API error: {"error":{"message":"Model Not Exist","type":"invalid_request_error","param":null,"code":"invalid_request_error"}}
[2025-05-31 18:17:11] Backup created: C:\Users\Lenovo\.spyder-py3\xtts_match_embed.py.bak15
[2025-05-31 18:17:11] Applied repaired code
[2025-05-31 18:17:11] FAILED: Maximum attempts reached
❌ Patch import failed: iter_4.py - name 'DONE' is not defined
❌ Patch import failed: iter_5.py - name 'DONE' is not defined
💀 CRITICAL FAILURE: name 'threading' is not defined
Traceback (most recent call last):
  File "c:\users\lenovo\.spyder-py3\untitled17.py", line 325, in <module>
    asyncio.run(main())
  File "C:\Users\Lenovo\anaconda3\envs\xtts_env\lib\site-packages\nest_asyncio.py", line 30, in run
    return loop.run_until_complete(task)
  File "C:\Users\Lenovo\anaconda3\envs\xtts_env\lib\site-packages\nest_asyncio.py", line 98, in run_until_complete
    return f.result()
  File "C:\Users\Lenovo\anaconda3\envs\xtts_env\lib\asyncio\futures.py", line 201, in result
    raise self._exception.with_traceback(self._exception_tb)
  File "C:\Users\Lenovo\anaconda3\envs\xtts_env\lib\asyncio\tasks.py", line 232, in __step
    result = coro.send(None)
  File "c:\users\lenovo\.spyder-py3\untitled17.py", line 315, in main
    await agent.run()
  File "c:\users\lenovo\.spyder-py3\untitled17.py", line 288, in run
    success, output = self.run_script()
  File "c:\users\lenovo\.spyder-py3\untitled17.py", line 179, in run_script
    threading.Thread(target=watchdog, daemon=True).start()
NameError: name 'threading' is not defined
❌ Patch import failed: iter_4.py - name 'DONE' is not defined
❌ Patch import failed: iter_4.py - name 'DONE' is not defined
❌ Patch import failed: iter_5.py - name 'DONE' is not defined
❌ Patch import failed: iter_5.py - name 'DONE' is not defined
💀 CRITICAL FAILURE: name 'threading' is not defined
Traceback (most recent call last):
  File "c:\users\lenovo\.spyder-py3\untitled17.py", line 325, in <module>
    asyncio.run(main())
  File "C:\Users\Lenovo\anaconda3\envs\xtts_env\lib\site-packages\nest_asyncio.py", line 30, in run
    return loop.run_until_complete(task)
  File "C:\Users\Lenovo\anaconda3\envs\xtts_env\lib\site-packages\nest_asyncio.py", line 98, in run_until_complete
    return f.result()
  File "C:\Users\Lenovo\anaconda3\envs\xtts_env\lib\asyncio\futures.py", line 201, in result
    raise self._exception.with_traceback(self._exception_tb)
  File "C:\Users\Lenovo\anaconda3\envs\xtts_env\lib\asyncio\tasks.py", line 232, in __step
    result = coro.send(None)
  File "c:\users\lenovo\.spyder-py3\untitled17.py", line 315, in main
    await agent.run()
  File "c:\users\lenovo\.spyder-py3\untitled17.py", line 288, in run
    success, output = self.run_script()
  File "c:\users\lenovo\.spyder-py3\untitled17.py", line 179, in run_script
    threading.Thread(target=watchdog, daemon=True).start()
NameError: name 'threading' is not defined
💀 CRITICAL FAILURE: name 'threading' is not defined
Traceback (most recent call last):
  File "c:\users\lenovo\.spyder-py3\untitled17.py", line 325, in <module>
    asyncio.run(main())
  File "C:\Users\Lenovo\anaconda3\envs\xtts_env\lib\site-packages\nest_asyncio.py", line 30, in run
    return loop.run_until_complete(task)
  File "C:\Users\Lenovo\anaconda3\envs\xtts_env\lib\site-packages\nest_asyncio.py", line 98, in run_until_complete
    return f.result()
  File "C:\Users\Lenovo\anaconda3\envs\xtts_env\lib\asyncio\futures.py", line 201, in result
    raise self._exception.with_traceback(self._exception_tb)
  File "C:\Users\Lenovo\anaconda3\envs\xtts_env\lib\asyncio\tasks.py", line 232, in __step
    result = coro.send(None)
  File "c:\users\lenovo\.spyder-py3\untitled17.py", line 315, in main
    await agent.run()
  File "c:\users\lenovo\.spyder-py3\untitled17.py", line 288, in run
    success, output = self.run_script()
  File "c:\users\lenovo\.spyder-py3\untitled17.py", line 179, in run_script
    threading.Thread(target=watchdog, daemon=True).start()
NameError: name 'threading' is not defined
❌ Patch import failed: iter_4.py - name 'DONE' is not defined
❌ Patch import failed: iter_4.py - name 'DONE' is not defined
❌ Patch import failed: iter_4.py - name 'DONE' is not defined
❌ Patch import failed: iter_5.py - name 'DONE' is not defined
❌ Patch import failed: iter_5.py - name 'DONE' is not defined
❌ Patch import failed: iter_5.py - name 'DONE' is not defined
💀 CRITICAL FAILURE: name 'threading' is not defined
Traceback (most recent call last):
  File "c:\users\lenovo\.spyder-py3\untitled17.py", line 325, in <module>
    asyncio.run(main())
  File "C:\Users\Lenovo\anaconda3\envs\xtts_env\lib\site-packages\nest_asyncio.py", line 30, in run
    return loop.run_until_complete(task)
  File "C:\Users\Lenovo\anaconda3\envs\xtts_env\lib\site-packages\nest_asyncio.py", line 98, in run_until_complete
    return f.result()
  File "C:\Users\Lenovo\anaconda3\envs\xtts_env\lib\asyncio\futures.py", line 201, in result
    raise self._exception.with_traceback(self._exception_tb)
  File "C:\Users\Lenovo\anaconda3\envs\xtts_env\lib\asyncio\tasks.py", line 232, in __step
    result = coro.send(None)
  File "c:\users\lenovo\.spyder-py3\untitled17.py", line 315, in main
    await agent.run()
  File "c:\users\lenovo\.spyder-py3\untitled17.py", line 288, in run
    success, output = self.run_script()
  File "c:\users\lenovo\.spyder-py3\untitled17.py", line 179, in run_script
    threading.Thread(target=watchdog, daemon=True).start()
NameError: name 'threading' is not defined
💀 CRITICAL FAILURE: name 'threading' is not defined
Traceback (most recent call last):
  File "c:\users\lenovo\.spyder-py3\untitled17.py", line 325, in <module>
    asyncio.run(main())
  File "C:\Users\Lenovo\anaconda3\envs\xtts_env\lib\site-packages\nest_asyncio.py", line 30, in run
    return loop.run_until_complete(task)
  File "C:\Users\Lenovo\anaconda3\envs\xtts_env\lib\site-packages\nest_asyncio.py", line 98, in run_until_complete
    return f.result()
  File "C:\Users\Lenovo\anaconda3\envs\xtts_env\lib\asyncio\futures.py", line 201, in result
    raise self._exception.with_traceback(self._exception_tb)
  File "C:\Users\Lenovo\anaconda3\envs\xtts_env\lib\asyncio\tasks.py", line 232, in __step
    result = coro.send(None)
  File "c:\users\lenovo\.spyder-py3\untitled17.py", line 315, in main
    await agent.run()
  File "c:\users\lenovo\.spyder-py3\untitled17.py", line 288, in run
    success, output = self.run_script()
  File "c:\users\lenovo\.spyder-py3\untitled17.py", line 179, in run_script
    threading.Thread(target=watchdog, daemon=True).start()
NameError: name 'threading' is not defined
💀 CRITICAL FAILURE: name 'threading' is not defined
Traceback (most recent call last):
  File "c:\users\lenovo\.spyder-py3\untitled17.py", line 325, in <module>
    asyncio.run(main())
  File "C:\Users\Lenovo\anaconda3\envs\xtts_env\lib\site-packages\nest_asyncio.py", line 30, in run
    return loop.run_until_complete(task)
  File "C:\Users\Lenovo\anaconda3\envs\xtts_env\lib\site-packages\nest_asyncio.py", line 98, in run_until_complete
    return f.result()
  File "C:\Users\Lenovo\anaconda3\envs\xtts_env\lib\asyncio\futures.py", line 201, in result
    raise self._exception.with_traceback(self._exception_tb)
  File "C:\Users\Lenovo\anaconda3\envs\xtts_env\lib\asyncio\tasks.py", line 232, in __step
    result = coro.send(None)
  File "c:\users\lenovo\.spyder-py3\untitled17.py", line 315, in main
    await agent.run()
  File "c:\users\lenovo\.spyder-py3\untitled17.py", line 288, in run
    success, output = self.run_script()
  File "c:\users\lenovo\.spyder-py3\untitled17.py", line 179, in run_script
    threading.Thread(target=watchdog, daemon=True).start()
NameError: name 'threading' is not defined
❌ Patch import failed: iter_4.py - name 'DONE' is not defined
❌ Patch import failed: iter_4.py - name 'DONE' is not defined
❌ Patch import failed: iter_4.py - name 'DONE' is not defined
❌ Patch import failed: iter_4.py - name 'DONE' is not defined
❌ Patch import failed: iter_5.py - name 'DONE' is not defined
❌ Patch import failed: iter_5.py - name 'DONE' is not defined
❌ Patch import failed: iter_5.py - name 'DONE' is not defined
❌ Patch import failed: iter_5.py - name 'DONE' is not defined
❌ Patch import failed: iter_4.py - name 'DONE' is not defined
❌ Patch import failed: iter_4.py - name 'DONE' is not defined
❌ Patch import failed: iter_4.py - name 'DONE' is not defined
❌ Patch import failed: iter_4.py - name 'DONE' is not defined
❌ Patch import failed: iter_4.py - name 'DONE' is not defined
❌ Patch import failed: iter_5.py - name 'DONE' is not defined
❌ Patch import failed: iter_5.py - name 'DONE' is not defined
❌ Patch import failed: iter_5.py - name 'DONE' is not defined
❌ Patch import failed: iter_5.py - name 'DONE' is not defined
❌ Patch import failed: iter_5.py - name 'DONE' is not defined
❌ Patch import failed: iter_4.py - name 'DONE' is not defined
❌ Patch import failed: iter_4.py - name 'DONE' is not defined
❌ Patch import failed: iter_4.py - name 'DONE' is not defined
❌ Patch import failed: iter_4.py - name 'DONE' is not defined
❌ Patch import failed: iter_4.py - name 'DONE' is not defined
❌ Patch import failed: iter_4.py - name 'DONE' is not defined
❌ Patch import failed: iter_5.py - name 'DONE' is not defined
❌ Patch import failed: iter_5.py - name 'DONE' is not defined
❌ Patch import failed: iter_5.py - name 'DONE' is not defined
❌ Patch import failed: iter_5.py - name 'DONE' is not defined
❌ Patch import failed: iter_5.py - name 'DONE' is not defined
❌ Patch import failed: iter_5.py - name 'DONE' is not defined
❌ Patch import failed: iter_4.py - name 'DONE' is not defined
❌ Patch import failed: iter_4.py - name 'DONE' is not defined
❌ Patch import failed: iter_4.py - name 'DONE' is not defined
❌ Patch import failed: iter_4.py - name 'DONE' is not defined
❌ Patch import failed: iter_4.py - name 'DONE' is not defined
❌ Patch import failed: iter_4.py - name 'DONE' is not defined
❌ Patch import failed: iter_4.py - name 'DONE' is not defined
❌ Patch import failed: iter_5.py - name 'DONE' is not defined
❌ Patch import failed: iter_5.py - name 'DONE' is not defined
❌ Patch import failed: iter_5.py - name 'DONE' is not defined
❌ Patch import failed: iter_5.py - name 'DONE' is not defined
❌ Patch import failed: iter_5.py - name 'DONE' is not defined
❌ Patch import failed: iter_5.py - name 'DONE' is not defined
❌ Patch import failed: iter_5.py - name 'DONE' is not defined
💥 Script failed:
File "C:\Users\Lenovo\.spyder-py3\xtts_match_embed.py", line 25
python "C:\Users\Lenovo\.spyder-py3\xtts_match_embed.py"
^
SyntaxError: (unicode error) 'unicodeescape' codec can't decode bytes in position 2-3: truncated \UXXXXXXXX escape
💥 Script failed:
File "C:\Users\Lenovo\.spyder-py3\xtts_match_embed.py", line 25
python "C:\Users\Lenovo\.spyder-py3\xtts_match_embed.py"
^
SyntaxError: (unicode error) 'unicodeescape' codec can't decode bytes in position 2-3: truncated \UXXXXXXXX escape
💥 Script failed:
File "C:\Users\Lenovo\.spyder-py3\xtts_match_embed.py", line 25
python "C:\Users\Lenovo\.spyder-py3\xtts_match_embed.py"
^
SyntaxError: (unicode error) 'unicodeescape' codec can't decode bytes in position 2-3: truncated \UXXXXXXXX escape
💥 Script failed:
File "C:\Users\Lenovo\.spyder-py3\xtts_match_embed.py", line 25
python "C:\Users\Lenovo\.spyder-py3\xtts_match_embed.py"
^
SyntaxError: (unicode error) 'unicodeescape' codec can't decode bytes in position 2-3: truncated \UXXXXXXXX escape
💥 Script failed:
File "C:\Users\Lenovo\.spyder-py3\xtts_match_embed.py", line 25
python "C:\Users\Lenovo\.spyder-py3\xtts_match_embed.py"
^
SyntaxError: (unicode error) 'unicodeescape' codec can't decode bytes in position 2-3: truncated \UXXXXXXXX escape
💥 Script failed:
File "C:\Users\Lenovo\.spyder-py3\xtts_match_embed.py", line 25
python "C:\Users\Lenovo\.spyder-py3\xtts_match_embed.py"
^
SyntaxError: (unicode error) 'unicodeescape' codec can't decode bytes in position 2-3: truncated \UXXXXXXXX escape
💥 Script failed:
File "C:\Users\Lenovo\.spyder-py3\xtts_match_embed.py", line 25
python "C:\Users\Lenovo\.spyder-py3\xtts_match_embed.py"
^
SyntaxError: (unicode error) 'unicodeescape' codec can't decode bytes in position 2-3: truncated \UXXXXXXXX escape
💥 Script failed:
Traceback (most recent call last):
File "C:\Users\Lenovo\.spyder-py3\xtts_match_embed.py", line 33, in <module>
main_loop()
NameError: name 'main_loop' is not defined
💥 Script failed:
Traceback (most recent call last):
File "C:\Users\Lenovo\.spyder-py3\xtts_match_embed.py", line 33, in <module>
main_loop()
NameError: name 'main_loop' is not defined
💥 Script failed:
Traceback (most recent call last):
File "C:\Users\Lenovo\.spyder-py3\xtts_match_embed.py", line 33, in <module>
main_loop()
NameError: name 'main_loop' is not defined
💥 Script failed:
Traceback (most recent call last):
File "C:\Users\Lenovo\.spyder-py3\xtts_match_embed.py", line 33, in <module>
main_loop()
NameError: name 'main_loop' is not defined
💥 Script failed:
Traceback (most recent call last):
File "C:\Users\Lenovo\.spyder-py3\xtts_match_embed.py", line 33, in <module>
main_loop()
NameError: name 'main_loop' is not defined
💥 Script failed:
Traceback (most recent call last):
File "C:\Users\Lenovo\.spyder-py3\xtts_match_embed.py", line 33, in <module>
main_loop()
NameError: name 'main_loop' is not defined
💥 Script failed:
Traceback (most recent call last):
File "C:\Users\Lenovo\.spyder-py3\xtts_match_embed.py", line 33, in <module>
main_loop()
NameError: name 'main_loop' is not defined
[2025-06-02 14:35:34] Starting main execution loop
[2025-06-02 14:35:34] Script initialized successfully
❌ Patch import failed: iter_4.py - name 'DONE' is not defined
❌ Patch import failed: iter_4.py - name 'DONE' is not defined
❌ Patch import failed: iter_4.py - name 'DONE' is not defined
❌ Patch import failed: iter_4.py - name 'DONE' is not defined
❌ Patch import failed: iter_4.py - name 'DONE' is not defined
❌ Patch import failed: iter_4.py - name 'DONE' is not defined
❌ Patch import failed: iter_4.py - name 'DONE' is not defined
❌ Patch import failed: iter_4.py - name 'DONE' is not defined
❌ Patch import failed: iter_5.py - name 'DONE' is not defined
❌ Patch import failed: iter_5.py - name 'DONE' is not defined
❌ Patch import failed: iter_5.py - name 'DONE' is not defined
❌ Patch import failed: iter_5.py - name 'DONE' is not defined
❌ Patch import failed: iter_5.py - name 'DONE' is not defined
❌ Patch import failed: iter_5.py - name 'DONE' is not defined
❌ Patch import failed: iter_5.py - name 'DONE' is not defined
❌ Patch import failed: iter_5.py - name 'DONE' is not defined
[2025-06-02 14:38:06] Starting main execution loop
[2025-06-02 14:38:06] Script initialized successfully
[2025-06-02 14:47:24] Starting main execution loop
[2025-06-02 14:47:24] Script initialized successfully
[2025-06-02 14:48:55] Starting main execution loop
[2025-06-02 14:48:55] Script initialized successfully
[2025-06-02 14:50:12] Starting main execution loop
[2025-06-02 14:50:12] Script initialized successfully
[2025-06-02 14:50:34] Starting main execution loop
[2025-06-02 14:50:34] Script initialized successfully
